Workbook
Name inp_ticker: 'Inputs'!C4
Name inp_name: 'Inputs'!E4
Name inp_rev_ttm: 'Inputs'!C9
Name inp_ebit_ttm: 'Inputs'!C10
Name inp_tax_ttm: 'Inputs'!C11
Name inp_da_ttm: 'Inputs'!C12
Name inp_capex_ttm: 'Inputs'!C13
Name inp_dNWC_ttm: 'Inputs'!C14
Name inp_rd_ttm: 'Inputs'!C15
Name inp_rent_ttm: 'Inputs'!C16
Name inp_g1: 'Inputs'!C20
Name inp_g2: 'Inputs'!C21
Name inp_g3: 'Inputs'!C22
Name inp_g4: 'Inputs'!C23
Name inp_g5: 'Inputs'!C24
Name inp_m5: 'Inputs'!C25
Name inp_m10: 'Inputs'!C26
Name inp_tax_norm: 'Inputs'!C27
Name inp_da_pct: 'Inputs'!C28
Name inp_capex_pct: 'Inputs'!C29
Name inp_nwc_pct: 'Inputs'!C30
Name inp_rd_pct: 'Inputs'!C31
Name inp_rent_pct: 'Inputs'!C32
Name inp_rf: 'Inputs'!C37
Name inp_erp: 'Inputs'!C38
Name inp_beta: 'Inputs'!C39
Name calc_ke: 'Inputs'!C40
Name inp_kd: 'Inputs'!C41
Name inp_dw: 'Inputs'!C42
Name calc_wacc: 'Inputs'!C43
Name inp_gt: 'Inputs'!C44
Name inp_cash: 'Inputs'!C49
Name inp_debt: 'Inputs'!C50
Name calc_lease_debt: 'Inputs'!C51
Name inp_other_adj: 'Inputs'!C52
Name inp_basic_shares: 'Inputs'!C53
Name inp_px: 'Inputs'!C54
Name calc_diluted_shares: 'Inputs'!C55
Name inp_cap_rd_toggle: 'Inputs'!C58
Name inp_cap_lease_toggle: 'Inputs'!C59
Name log_run_id: 'Agent Log'!$C$6
Name log_status: 'Agent Log'!$E$6
Name log_start_ts: 'Agent Log'!$C$7
Name log_end_ts: 'Agent Log'!$E$7
Name log_template_version: 'Agent Log'!$C$9
Name log_agent_version: 'Agent Log'!$E$9
Name log_model: 'Agent Log'!$C$10
Name log_engine: 'Agent Log'!$E$10
Name log_data_sources: 'Agent Log'!$C$11
Name log_currency_units: 'Agent Log'!$E$11
Name log_tokens: 'Agent Log'!$C$12
Name log_cost_usd: 'Agent Log'!$E$12
Name log_actions_header: 'Agent Log'!$B$16:$J$16
Name log_actions_firstrow: 'Agent Log'!$B$17:$J$17
Name log_assumptions_header: 'Agent Log'!$B$220:$K$220
Name log_assumptions_firstrow: 'Agent Log'!$B$221:$K$221
Name out_run_id: 'Output'!$C$5
Name out_value_per_share: 'Output'!$C$6
Name out_equity_value: 'Output'!$C$7
Name out_enterprise_value: 'Output'!$C$8

Sheet README
B2: Bank‑Style Valuation Template (TTM + Treasury Stock Method + R&D + Operating Leases)
B4: As-of: 2026-02-14 | Version: v3 (Sheets + Logbook)
B6: Workflow
B7: 1) Fill Inputs (TTM + neutral assumptions in column C).
B8: 2) Review scenario overrides in Inputs columns G/H/I and set scenario weights (G63:I63).
B9: 3) Populate Dilution (TSM); optionally populate R&D and Lease modules.
B10: 4) Confirm Checks has no FAIL and Output weighted fields are populated.
B11: 5) Generate memo from weighted + scenario outputs; log rationale in Agent Log.
B12: Legend
B13: Blue text + yellow fill = editable input
B14: Red italic text = guidance / guardrails
B15: Light blue fill = key outputs
... B20: Sheets engine (Google Sheets API): store spreadsheet in Google Drive, write named ranges, read Output.

Sheet Inputs
B2: CONTROL PANEL (Blue/yellow = editable inputs)
B4: Ticker | D4: Company name
B5: Currency / Units | C5: USD ($mm) | D5: Base year | E5: TTM (Trailing Twelve Months)
B7: TTM BASE YEAR (Operating)
B9: Revenue (TTM) | D9: Input | E9: TTM = sum last 4 quarters. Reconcile FY+interim if mixing.
B10: EBIT (TTM, reported) | D10: Input
B11: Effective tax rate (TTM) | D11: Input
B12: Depreciation & amortization (TTM) | D12: Input
B13: Capex (TTM, PPE purchases) | D13: Input
B14: ΔNet working capital (TTM) | D14: Input
B15: R&D expense (TTM) | D15: Input
B16: Rent/operating lease expense (TTM) | D16: Input
B18: FORECAST ASSUMPTIONS | G18: SCENARIO ASSUMPTIONS
G19: Pessimistic | H19: Neutral | I19: Optimistic
B20: Revenue growth Year 1 | C20: 0.05 | D20: Editable assumption | E20: Growth fades linearly from Year 5 to terminal growth by Year 10. | G20: =C20-0.02 | H20: =C20 | I20: =C20+0.015
B21: Revenue growth Year 2 | C21: 0.04 | D21: Editable assumption | G21: =C21-0.02 | H21: =C21 | I21: =C21+0.015
B22: Revenue growth Year 3 | C22: 0.03 | D22: Editable assumption | G22: =C22-0.02 | H22: =C22 | I22: =C22+0.015
B23: Revenue growth Year 4 | C23: 0.03 | D23: Editable assumption | G23: =C23-0.02 | H23: =C23 | I23: =C23+0.015
B24: Revenue growth Year 5 | C24: 0.03 | D24: Editable assumption | G24: =C24-0.02 | H24: =C24 | I24: =C24+0.015
B25: Target EBIT margin (by Year 5) | C25: 0.3 | D25: Editable assumption | G25: =C25-0.03 | H25: =C25 | I25: =C25+0.03
B26: Terminal EBIT margin (by Year 10) | C26: 0.3 | D26: Editable assumption | G26: =C26-0.03 | H26: =C26 | I26: =C26+0.03
B27: Tax rate (normalized) | C27: 0.18 | D27: Editable assumption | G27: =C27+0.005 | H27: =C27 | I27: =MAX(C27-0.005,0)
B28: D&A % of revenue | C28: 0.03 | D28: Editable assumption | G28: =C28 | H28: =C28 | I28: =C28
B29: Capex % of revenue | C29: 0.02 | D29: Editable assumption | G29: =C29+0.005 | H29: =C29 | I29: =MAX(C29-0.005,0)
B30: ΔNWC % of revenue | C30: 0 | D30: Editable assumption | G30: =C30+0.005 | H30: =C30 | I30: =C30-0.005
B31: R&D % of revenue | C31: 0.07 | D31: Editable assumption | G31: =MAX(C31-0.01,0) | H31: =C31 | I31: =C31+0.01
B32: Rent/lease expense % of revenue | C32: 0.01 | D32: Editable assumption | G32: =C32+0.003 | H32: =C32 | I32: =MAX(C32-0.003,0)
B35: RISK & DISCOUNTING (WACC) — Guardrail: g ≤ rf
G36: Pessimistic | H36: Neutral | I36: Optimistic
B37: Risk‑free rate (rf) | C37: 0.0425 | D37: Input | G37: =C37 | H37: =C37 | I37: =C37
B38: Equity risk premium (ERP) | C38: 0.05 | D38: Input | G38: =C38+0.005 | H38: =C38 | I38: =MAX(C38-0.005,0)
B39: Levered beta (βL) | C39: 1.1 | D39: Input | G39: =C39+0.10 | H39: =C39 | I39: =MAX(C39-0.10,0)
B40: Cost of equity (ke) | C40: =C37 + C39*C38 | D40: Calculated | G40: =G37 + G39*G38 | H40: =H37 + H39*H38 | I40: =I37 + I39*I38
B41: Pre‑tax cost of debt (kd) | C41: 0.055 | D41: Input | G41: =C41+0.005 | H41: =C41 | I41: =MAX(C41-0.005,0)
B42: Target debt weight (Dw) | C42: 0.1 | D42: Input | G42: =MIN(C42+0.05,0.80) | H42: =C42 | I42: =MAX(C42-0.05,0)
B43: WACC | C43: =C40*(1-C42) + C41*(1-C27)*C42 | D43: Calculated | G43: =G40*(1-G42) + G41*(1-G27)*G42 | H43: =H40*(1-H42) + H41*(1-H27)*H42 | I43: =I40*(1-I42) + I41*(1-I27)*I42
B44: Terminal growth (g) | C44: 0.025 | D44: Input | E44: Hard stops: g ≤ rf and WACC > g. | G44: =MAX(C44-0.0075,0.005) | H44: =C44 | I44: =MIN(C44+0.005,I37-0.0025)
B47: EQUITY BRIDGE & SHARES
B49: Cash & marketable securities | D49: Input
B50: Total debt (ex‑leases) | D50: Input
...

Sheet Dilution (TSM)
B2: DILUTION — TREASURY STOCK METHOD (TSM)
B4: Average share price (P) | C4: =Inputs!C54
B5: Basic shares (mm) | C5: =Inputs!C53
C6: Enter tranches below. OTM options => 0 incremental shares.
B8: Instrument | C8: Count (mm) | D8: Strike (K) | E8: Type (Option/Warrant/RSU) | F8: Incremental shares (mm) | G8: Notes
F9: =IF(UPPER(E9)="RSU",C9,IF(AND(C9<>"",D9<>"",$C$4<>""),C9*MAX(0,1-D9/$C$4),""))
F10: =IF(UPPER(E10)="RSU",C10,IF(AND(C10<>"",D10<>"",$C$4<>""),C10*MAX(0,1-D10/$C$4),""))
F11: =IF(UPPER(E11)="RSU",C11,IF(AND(C11<>"",D11<>"",$C$4<>""),C11*MAX(0,1-D11/$C$4),""))
F12: =IF(UPPER(E12)="RSU",C12,IF(AND(C12<>"",D12<>"",$C$4<>""),C12*MAX(0,1-D12/$C$4),""))
F13: =IF(UPPER(E13)="RSU",C13,IF(AND(C13<>"",D13<>"",$C$4<>""),C13*MAX(0,1-D13/$C$4),""))
C14: =C25 | F14: =IF(UPPER(E14)="RSU",C14,IF(AND(C14<>"",D14<>"",$C$4<>""),C14*MAX(0,1-D14/$C$4),""))
F15: =IF(UPPER(E15)="RSU",C15,IF(AND(C15<>"",D15<>"",$C$4<>""),C15*MAX(0,1-D15/$C$4),""))
F16: =IF(UPPER(E16)="RSU",C16,IF(AND(C16<>"",D16<>"",$C$4<>""),C16*MAX(0,1-D16/$C$4),""))
F17: =IF(UPPER(E17)="RSU",C17,IF(AND(C17<>"",D17<>"",$C$4<>""),C17*MAX(0,1-D17/$C$4),""))
F18: =IF(UPPER(E18)="RSU",C18,IF(AND(C18<>"",D18<>"",$C$4<>""),C18*MAX(0,1-D18/$C$4),""))
F19: =IF(UPPER(E19)="RSU",C19,IF(AND(C19<>"",D19<>"",$C$4<>""),C19*MAX(0,1-D19/$C$4),""))
F20: =IF(UPPER(E20)="RSU",C20,IF(AND(C20<>"",D20<>"",$C$4<>""),C20*MAX(0,1-D20/$C$4),""))
B22: TSM SUMMARY
B24: Total incremental shares (mm) | C24: =SUM(F9:F20)
B25: Diluted shares (mm) | C25: =C5+C24

Sheet R&D Capitalization
B2: R&D CAPITALIZATION (OPEX → CAPEX)
B4: Use module? (YES/NO) | C4: =Inputs!C58 | F4: Populate past R&D for at least chosen life; outputs feed DCF adjustments.
B5: Amortization life (years) | C5: 5
B7: INPUT: HISTORICAL R&D (USD mm)
B8: Year | C8: R&D expense | D8: % unamortized | E8: Unamortized | F8: Amortization | G8: Notes
B9: Year 0 (TTM) | C9: =Inputs!C15 | D9: =MAX(0,($C$5-0)/$C$5) | E9: =C9*D9 | F9: =IF(C9="","",C9/$C$5)
B10: Year -1 | D10: =MAX(0,($C$5-1)/$C$5) | E10: =C10*D10 | F10: =IF(C10="","",C10/$C$5)
B11: Year -2 | D11: =MAX(0,($C$5-2)/$C$5) | E11: =C11*D11 | F11: =IF(C11="","",C11/$C$5)
B12: Year -3 | D12: =MAX(0,($C$5-3)/$C$5) | E12: =C12*D12 | F12: =IF(C12="","",C12/$C$5)
B13: Year -4 | D13: =MAX(0,($C$5-4)/$C$5) | E13: =C13*D13 | F13: =IF(C13="","",C13/$C$5)
B14: Year -5 | D14: =MAX(0,($C$5-5)/$C$5) | E14: =C14*D14 | F14: =IF(C14="","",C14/$C$5)
B15: Year -6 | D15: =MAX(0,($C$5-6)/$C$5) | E15: =C15*D15 | F15: =IF(C15="","",C15/$C$5)
B16: Year -7 | C16: =C22 | D16: =MAX(0,($C$5-7)/$C$5) | E16: =C16*D16 | F16: =IF(C16="","",C16/$C$5)
B17: Year -8 | C17: =C23 | D17: =MAX(0,($C$5-8)/$C$5) | E17: =C17*D17 | F17: =IF(C17="","",C17/$C$5)
B18: Year -9 | C18: =C24 | D18: =MAX(0,($C$5-9)/$C$5) | E18: =C18*D18 | F18: =IF(C18="","",C18/$C$5)
C19: =C25
B20: OUTPUTS
B22: R&D asset (unamortized) | C22: =IF(UPPER(C4)="YES",SUM(E9:E18),0)
B23: R&D amortization (TTM) | C23: =IF(UPPER(C4)="YES",SUM(F9:F18),0)
B24: EBIT adjustment | C24: =IF(UPPER(C4)="YES",Inputs!C15-C23,0)
B25: R&D treated as capex (TTM) | C25: =IF(UPPER(C4)="YES",Inputs!C15,0)

Sheet Lease Capitalization
B2: OPERATING LEASE CAPITALIZATION
B4: Use module? (YES/NO) | C4: =Inputs!C59 | F4: Enter commitments Y1–Y5 + thereafter; outputs PV lease debt.
B5: Discount rate (pre‑tax kd) | C5: =Inputs!C41
B6: Lease life for depreciation (years) | C6: 10
B7: INPUT: LEASE COMMITMENTS (USD mm)
B8: Year | C8: Commitment | D8: Discount factor | E8: PV | F8: Notes
B9: Year 1 | D9: =1/(1+$C$5)^1 | E9: =C9*D9
B10: Year 2 | D10: =1/(1+$C$5)^2 | E10: =C10*D10
B11: Year 3 | D11: =1/(1+$C$5)^3 | E11: =C11*D11
B12: Year 4 | D12: =1/(1+$C$5)^4 | E12: =C12*D12
B13: Year 5 | D13: =1/(1+$C$5)^5 | E13: =C13*D13
B14: Thereafter (total) | E14: =IF(OR(C14="",C15="",$C$5=""),"",(C14/C15)*(1-(1+$C$5)^(-C15))/$C$5/(1+$C$5)^5) | F14: Assume distributed over N years (below).
B15: Assumed years for thereafter (N) | C15: 10 | F15: Document assumption if timing not disclosed.
B17: OUTPUTS
B19: PV of lease commitments (lease debt) | C19: =IF(UPPER(C4)="YES",SUM(E9:E13)+E14,0)
B20: Lease depreciation | C20: =IF(UPPER(C4)="YES",C19/$C$6,0)
B21: EBIT adjustment | C21: =IF(UPPER(C4)="YES",Inputs!C16-C20,0)

Sheet DCF
B2: DCF (FCFF) — TTM base year + optional R&D & lease capitalization
C8: Y0 (TTM) | D8: Y1 | E8: Y2 | F8: Y3 | G8: Y4 | H8: Y5 | I8: Y6 | J8: Y7 | K8: Y8 | L8: Y9 | M8: Y10
B9: Revenue | C9: =Inputs!C9 | D9: =C9*(1+D10) | E9: =D9*(1+E10) | F9: =E9*(1+F10) | G9: =F9*(1+G10) | H9: =G9*(1+H10) | I9: =H9*(1+I10) | J9: =I9*(1+J10) | K9: =J9*(1+K10) | L9: =K9*(1+L10)
B10: YoY growth | D10: =Inputs!C20 | E10: =Inputs!C21 | F10: =Inputs!C22 | G10: =Inputs!C23 | H10: =Inputs!C24 | I10: =Inputs!C44 + (Inputs!C24-Inputs!C44)*((10-6)/5) | J10: =Inputs!C44 + (Inputs!C24-Inputs!C44)*((10-7)/5) | K10: =Inputs!C44 + (Inputs!C24-Inputs!C44)*((10-8)/5) | L10: =Inputs!C44 + (Inputs!C24-Inputs!C44)*((10-9)/5)
B11: EBIT margin | C11: =IF(Inputs!C9=0,"",Inputs!C10/Inputs!C9) | D11: =$C$11 + (Inputs!C25-$C$11)*(1/5) | E11: =$C$11 + (Inputs!C25-$C$11)*(2/5) | F11: =$C$11 + (Inputs!C25-$C$11)*(3/5) | G11: =$C$11 + (Inputs!C25-$C$11)*(4/5) | H11: =$C$11 + (Inputs!C25-$C$11)*(5/5) | I11: =Inputs!C25 + (Inputs!C26-Inputs!C25)*((6-5)/5) | J11: =Inputs!C25 + (Inputs!C26-Inputs!C25)*((7-5)/5) | K11: =Inputs!C25 + (Inputs!C26-Inputs!C25)*((8-5)/5) | L11: =Inputs!C25 + (Inputs!C26-Inputs!C25)*((9-5)/5)
B12: EBIT (reported) | C12: =C9*C11 | D12: =D9*D11 | E12: =E9*E11 | F12: =F9*F11 | G12: =G9*G11 | H12: =H9*H11 | I12: =I9*I11 | J12: =J9*J11 | ... L12: =L9*L11
B13: R&D expense | C13: =Inputs!C15 | D13: =D9*Inputs!C31 | E13: =E9*Inputs!C31 | F13: =F9*Inputs!C31 | G13: =G9*Inputs!C31 | H13: =H9*Inputs!C31 | I13: =I9*Inputs!C31 | J13: =J9*Inputs!C31 | K13: =K9*Inputs!C31 | L13: =L9*Inputs!C31
B14: R&D amort. | C14: =IF(UPPER(Inputs!C58)="YES",C13/'R&D Capitalization'!$C$5,0) | D14: =IF(UPPER(Inputs!C58)="YES",D13/'R&D Capitalization'!$C$5,0) | E14: =IF(UPPER(Inputs!C58)="YES",E13/'R&D Capitalization'!$C$5,0) | F14: =IF(UPPER(Inputs!C58)="YES",F13/'R&D Capitalization'!$C$5,0) | G14: =IF(UPPER(Inputs!C58)="YES",G13/'R&D Capitalization'!$C$5,0) | H14: =IF(UPPER(Inputs!C58)="YES",H13/'R&D Capitalization'!$C$5,0) | I14: =IF(UPPER(Inputs!C58)="YES",I13/'R&D Capitalization'!$C$5,0) | J14: =IF(UPPER(Inputs!C58)="YES",J13/'R&D Capitalization'!$C$5,0) | K14: =IF(UPPER(Inputs!C58)="YES",K13/'R&D Capitalization'!$C$5,0) | L14: =IF(UPPER(Inputs!C58)="YES",L13/'R&D Capitalization'!$C$5,0)
B15: Rent/lease exp. | C15: =Inputs!C16 | D15: =D9*Inputs!C32 | E15: =E9*Inputs!C32 | F15: =F9*Inputs!C32 | G15: =G9*Inputs!C32 | H15: =H9*Inputs!C32 | I15: =I9*Inputs!C32 | J15: =J9*Inputs!C32 | K15: =K9*Inputs!C32 | L15: =L9*Inputs!C32
B16: Lease depreciation | C16: =IF(UPPER(Inputs!C59)="YES",'Lease Capitalization'!C20,0) | D16: =IF(UPPER(Inputs!C59)="YES",'Lease Capitalization'!C20,0) | E16: =IF(UPPER(Inputs!C59)="YES",'Lease Capitalization'!C20,0) | F16: =IF(UPPER(Inputs!C59)="YES",'Lease Capitalization'!C20,0) | G16: =IF(UPPER(Inputs!C59)="YES",'Lease Capitalization'!C20,0) | H16: =IF(UPPER(Inputs!C59)="YES",'Lease Capitalization'!C20,0) | I16: =IF(UPPER(Inputs!C59)="YES",'Lease Capitalization'!C20,0) | J16: =IF(UPPER(Inputs!C59)="YES",'Lease Capitalization'!C20,0) | K16: =IF(UPPER(Inputs!C59)="YES",'Lease Capitalization'!C20,0) | L16: =IF(UPPER(Inputs!C59)="YES",'Lease Capitalization'!C20,0)
B17: EBIT (adjusted) | C17: =C12+C13-C14+C15-C16 | D17: =D12+D13-D14+D15-D16 | E17: =E12+E13-E14+E15-E16 | F17: =F12+F13-F14+F15-F16 | G17: =G12+G13-G14+G15-G16 | H17: =H12+H13-H14+H15-H16 | I17: =I12+I13-I14+I15-I16 | J17: =J12+J13-J14+J15-J16 | ... L17: =L12+L13-L14+L15-L16
B18: Tax rate | C18: =Inputs!C27 | D18: =Inputs!C27 | E18: =Inputs!C27 | F18: =Inputs!C27 | G18: =Inputs!C27 | H18: =Inputs!C27 | I18: =Inputs!C27 | J18: =Inputs!C27 | K18: =Inputs!C27 | L18: =Inputs!C27
B19: NOPAT | C19: =C17*(1-C18) | D19: =D17*(1-D18) | E19: =E17*(1-E18) | F19: =F17*(1-F18) | G19: =G17*(1-G18) | H19: =H17*(1-H18) | I19: =I17*(1-I18) | J19: =J17*(1-J18) | ... L19: =L17*(1-L18)
B20: D&A | C20: =Inputs!C12 | D20: =D9*Inputs!C28 | E20: =E9*Inputs!C28 | F20: =F9*Inputs!C28 | G20: =G9*Inputs!C28 | H20: =H9*Inputs!C28 | I20: =I9*Inputs!C28 | J20: =J9*Inputs!C28 | K20: =K9*Inputs!C28 | L20: =L9*Inputs!C28
B21: Non‑cash addbacks | C21: =C20+C14+C16 | D21: =D20+D14+D16 | E21: =E20+E14+E16 | F21: =F20+F14+F16 | G21: =G20+G14+G16 | H21: =H20+H14+H16 | I21: =I20+I14+I16 | J21: =J20+J14+J16 | ... L21: =L20+L14+L16
B22: Capex (PPE) | C22: =Inputs!C13 | D22: =D9*Inputs!C29 | E22: =E9*Inputs!C29 | F22: =F9*Inputs!C29 | G22: =G9*Inputs!C29 | H22: =H9*Inputs!C29 | I22: =I9*Inputs!C29 | J22: =J9*Inputs!C29 | K22: =K9*Inputs!C29 | L22: =L9*Inputs!C29
B23: R&D capex | C23: =IF(UPPER(Inputs!C58)="YES",C13,0) | D23: =IF(UPPER(Inputs!C58)="YES",D13,0) | E23: =IF(UPPER(Inputs!C58)="YES",E13,0) | F23: =IF(UPPER(Inputs!C58)="YES",F13,0) | G23: =IF(UPPER(Inputs!C58)="YES",G13,0) | H23: =IF(UPPER(Inputs!C58)="YES",H13,0) | I23: =IF(UPPER(Inputs!C58)="YES",I13,0) | J23: =IF(UPPER(Inputs!C58)="YES",J13,0) | K23: =IF(UPPER(Inputs!C58)="YES",K13,0) | L23: =IF(UPPER(Inputs!C58)="YES",L13,0)
B24: ΔNWC | C24: =Inputs!C14 | D24: =D9*Inputs!C30 | E24: =E9*Inputs!C30 | F24: =F9*Inputs!C30 | G24: =G9*Inputs!C30 | H24: =H9*Inputs!C30 | I24: =I9*Inputs!C30 | J24: =J9*Inputs!C30 | K24: =K9*Inputs!C30 | L24: =L9*Inputs!C30
B25: Reinvestment | C25: =C22+C23+C24 | D25: =D22+D23+D24 | E25: =E22+E23+E24 | F25: =F22+F23+F24 | G25: =G22+G23+G24 | H25: =H22+H23+H24 | I25: =I22+I23+I24 | J25: =J22+J23+J24 | ... L25: =L22+L23+L24
B26: FCFF | C26: =C19+C21-C25 | D26: =D19+D21-D25 | E26: =E19+E21-E25 | F26: =F19+F21-F25 | G26: =G19+G21-G25 | H26: =H19+H21-H25 | I26: =I19+I21-I25 | J26: =J19+J21-J25 | ... L26: =L19+L21-L25
B27: Discount factor | D27: =1/(1+Inputs!C43)^1 | E27: =1/(1+Inputs!C43)^2 | F27: =1/(1+Inputs!C43)^3 | G27: =1/(1+Inputs!C43)^4 | H27: =1/(1+Inputs!C43)^5 | I27: =1/(1+Inputs!C43)^6 | J27: =1/(1+Inputs!C43)^7 | K27: =1/(1+Inputs!C43)^8 | L27: =1/(1+Inputs!C43)^9
B28: PV of FCFF | D28: =D26*D27 | E28: =E26*E27 | F28: =F26*F27 | G28: =G26*G27 | H28: =H26*H27 | I28: =I26*I27 | J28: =J26*J27 | K28: =K26*K27 | L28: =L26*L27
B30: TERMINAL VALUE & EQUITY VALUE
B32: Terminal year FCFF (Y10) | C32: =L26
B33: Terminal value | C33: =C32*(1+Inputs!C44)/(Inputs!C43-Inputs!C44)
B34: PV of terminal value | C34: =C33*L27
B35: Enterprise value (EV) | C35: =SUM(D28:L28)+C34
B37: Equity value | C37: =C35-Inputs!C50-Inputs!C51+Inputs!C49+Inputs!C52
B38: Diluted shares (mm) | C38: =Inputs!C55
B39: Implied value / share | C39: =C37/C38
B43: SCENARIO: PESSIMISTIC CASE
B44: Uses Inputs!G20:I44 scenario controls
C45: Y0 (TTM) | D45: Y1 | E45: Y2 | F45: Y3 | G45: Y4 | H45: Y5 | I45: Y6 | J45: Y7 | K45: Y8 | L45: Y9 | M45: Y10
B46: Revenue | C46: =Inputs!C9 | D46: =C46*(1+D47) | E46: =D46*(1+E47) | F46: =E46*(1+F47) | G46: =F46*(1+G47) | H46: =G46*(1+H47) | I46: =H46*(1+I47) | J46: =I46*(1+J47) | K46: =J46*(1+K47) | L46: =K46*(1+L47)
B47: YoY growth | D47: =Inputs!G20 | E47: =Inputs!G21 | F47: =Inputs!G22 | G47: =Inputs!G23 | H47: =Inputs!G24 | I47: =Inputs!G44 + (Inputs!G24-Inputs!G44)*((10-6)/5) | J47: =Inputs!G44 + (Inputs!G24-Inputs!G44)*((10-7)/5) | K47: =Inputs!G44 + (Inputs!G24-Inputs!G44)*((10-8)/5) | L47: =Inputs!G44 + (Inputs!G24-Inputs!G44)*((10-9)/5)
B48: EBIT margin | C48: =IF(Inputs!C9=0,"",Inputs!C10/Inputs!C9) | D48: =$C$48 + (Inputs!G25-$C$48)*(1/5) | E48: =$C$48 + (Inputs!G25-$C$48)*(2/5) | F48: =$C$48 + (Inputs!G25-$C$48)*(3/5) | G48: =$C$48 + (Inputs!G25-$C$48)*(4/5) | H48: =$C$48 + (Inputs!G25-$C$48)*(5/5) | I48: =Inputs!G25 + (Inputs!G26-Inputs!G25)*((6-5)/5) | J48: =Inputs!G25 + (Inputs!G26-Inputs!G25)*((7-5)/5) | K48: =Inputs!G25 + (Inputs!G26-Inputs!G25)*((8-5)/5) | L48: =Inputs!G25 + (Inputs!G26-Inputs!G25)*((9-5)/5)
B49: EBIT (reported) | C49: =C46*C48 | D49: =D46*D48 | E49: =E46*E48 | F49: =F46*F48 | G49: =G46*G48 | H49: =H46*H48 | I49: =I46*I48 | J49: =J46*J48 | ... L49: =L46*L48
B50: R&D expense | C50: =Inputs!C15 | D50: =D46*Inputs!G31 | E50: =E46*Inputs!G31 | F50: =F46*Inputs!G31 | G50: =G46*Inputs!G31 | H50: =H46*Inputs!G31 | I50: =I46*Inputs!G31 | J50: =J46*Inputs!G31 | K50: =K46*Inputs!G31 | L50: =L46*Inputs!G31
B51: R&D amort. | C51: =IF(UPPER(Inputs!C58)="YES",C50/'R&D Capitalization'!$C$5,0) | D51: =IF(UPPER(Inputs!C58)="YES",D50/'R&D Capitalization'!$C$5,0) | E51: =IF(UPPER(Inputs!C58)="YES",E50/'R&D Capitalization'!$C$5,0) | F51: =IF(UPPER(Inputs!C58)="YES",F50/'R&D Capitalization'!$C$5,0) | G51: =IF(UPPER(Inputs!C58)="YES",G50/'R&D Capitalization'!$C$5,0) | H51: =IF(UPPER(Inputs!C58)="YES",H50/'R&D Capitalization'!$C$5,0) | I51: =IF(UPPER(Inputs!C58)="YES",I50/'R&D Capitalization'!$C$5,0) | J51: =IF(UPPER(Inputs!C58)="YES",J50/'R&D Capitalization'!$C$5,0) | K51: =IF(UPPER(Inputs!C58)="YES",K50/'R&D Capitalization'!$C$5,0) | L51: =IF(UPPER(Inputs!C58)="YES",L50/'R&D Capitalization'!$C$5,0)
B52: Rent/lease exp. | C52: =Inputs!C16 | D52: =D46*Inputs!G32 | E52: =E46*Inputs!G32 | F52: =F46*Inputs!G32 | G52: =G46*Inputs!G32 | H52: =H46*Inputs!G32 | I52: =I46*Inputs!G32 | J52: =J46*Inputs!G32 | K52: =K46*Inputs!G32 | L52: =L46*Inputs!G32
...

Sheet Sensitivity
B2: SENSITIVITY — Value/Share vs WACC and Terminal g
B4: Base value/share | C4: =DCF!C39
B6: WACC \ g | C6: 0.015 | D6: 0.02 | E6: 0.025 | F6: 0.03 | G6: 0.035
B7: 0.07 | C7: (populate via agent scenario sweep) | D7: (populate via agent scenario sweep) | E7: (populate via agent scenario sweep) | F7: (populate via agent scenario sweep) | G7: (populate via agent scenario sweep)
B8: 0.08 | C8: (populate via agent scenario sweep) | D8: (populate via agent scenario sweep) | E8: (populate via agent scenario sweep) | F8: (populate via agent scenario sweep) | G8: (populate via agent scenario sweep)
B9: 0.09 | C9: (populate via agent scenario sweep) | D9: (populate via agent scenario sweep) | E9: (populate via agent scenario sweep) | F9: (populate via agent scenario sweep) | G9: (populate via agent scenario sweep)
B10: 0.1 | C10: (populate via agent scenario sweep) | D10: (populate via agent scenario sweep) | E10: (populate via agent scenario sweep) | F10: (populate via agent scenario sweep) | G10: (populate via agent scenario sweep)
B11: 0.11 | C11: (populate via agent scenario sweep) | D11: (populate via agent scenario sweep) | E11: (populate via agent scenario sweep) | F11: (populate via agent scenario sweep) | G11: (populate via agent scenario sweep)

Sheet Comps
B2: TRADING COMPS (stub) — agent populates peers + multiples
B4: Target revenue (TTM) | C4: =Inputs!C9
B5: Target EBIT (TTM) | C5: =Inputs!C10
B7: Ticker | C7: Company | D7: EV/EBIT | E7: EV/Revenue | F7: P/E | G7: Notes

Sheet Checks
B2: CHECKS — must have NO FAIL before publishing
B4: Check | C4: Status | D4: Notes
B5: Terminal g ≤ rf | C5: =IF(Inputs!C44<=Inputs!C37,"PASS","FAIL") | D5: Long‑run constraint.
B6: WACC > g | C6: =IF(Inputs!C43>Inputs!C44,"PASS","FAIL") | D6: DCF math requires WACC > g.
B7: Diluted shares ≥ basic | C7: =IF(Inputs!C55>=Inputs!C53,"PASS","FAIL") | D7: Check TSM table.
B8: Capex% ≥ 0 | C8: =IF(Inputs!C29>=0,"PASS","FAIL") | D8: Capex% must be non‑negative.
B9: Output exists | C9: =IFERROR(IF(DCF!C39>0,"PASS","REVIEW"),"FAIL") | D9: Fill missing inputs if FAIL.
B10: Scenario weights sum = 100% | C10: =IF(ABS(Inputs!G64-1)<0.0001,"PASS","FAIL") | D10: Required for weighted valuation.
B11: Pessimistic WACC > g | C11: =IF(Inputs!G43>Inputs!G44,"PASS","FAIL") | D11: Scenario hard constraint.
B12: Neutral WACC > g | C12: =IF(Inputs!C43>Inputs!C44,"PASS","FAIL") | D12: Scenario hard constraint.
B13: Optimistic WACC > g | C13: =IF(Inputs!I43>Inputs!I44,"PASS","FAIL") | D13: Scenario hard constraint.
B14: Pessimistic g <= rf | C14: =IF(Inputs!G44<=Inputs!G37,"PASS","FAIL") | D14: Long-run scenario constraint.
B15: Neutral g <= rf | C15: =IF(Inputs!C44<=Inputs!C37,"PASS","FAIL") | D15: Long-run scenario constraint.
B16: Optimistic g <= rf | C16: =IF(Inputs!I44<=Inputs!I37,"PASS","FAIL") | D16: Long-run scenario constraint.
B17: Weighted output exists | C17: =IFERROR(IF(Output!C6>0,"PASS","REVIEW"),"FAIL") | D17: Must exist before memo publish.

Sheet Sources
B2: DATA PROVENANCE — agent must write sources + dates
B4: Record source type, URL, as‑of date, and transforms (TTM calc, normalization).
B6: Field / Block | C6: Source Type | D6: Dataset / Doc | E6: URL | F6: As‑of date | G6: Notes

Sheet Story
B2: STORY → NUMBERS (memo prompts)
B4: Investment thesis (3–5 bullets)
B7: Growth story (drivers + fade)
B10: Profitability story (margin path)
B13: Reinvestment story (capex/R&D/NWC)
B16: Risk story (beta/WACC + sensitivities)
B19: Sanity checks (terminal, TV share)
B22: SCENARIO STORY GRID (link narrative to assumptions)
B23: Scenario | C23: Core narrative | D23: Linked operating driver | E23: KPI to track | F23: Disconfirming evidence | G23: Citation / source ID
B24: Pessimistic
B25: Neutral
B26: Optimistic
B28: Memo hooks: tie each key claim to scenario assumption and output range.

Sheet Output
B2: OUTPUT CONTRACT (agent reads only this block)
B5: Run ID | C5: =log_run_id
B6: Implied value / share | C6: =C15*C24 + C16*C25 + C17*C26 | D6: USD/share
B7: Equity value | C7: =C18*C24 + C19*C25 + C20*C26 | D7: USD mm
B8: Enterprise value (EV) | C8: =C21*C24 + C22*C25 + C23*C26 | D8: USD mm
B9: WACC | C9: =Inputs!C43
B10: Terminal growth (g) | C10: =Inputs!C44
B11: Debt (ex‑leases) | C11: =Inputs!C50 | D11: USD mm
B12: Lease debt (PV) | C12: ='Lease Capitalization'!C19 | D12: USD mm
B13: Cash | C13: =Inputs!C49 | D13: USD mm
B14: Diluted shares | C14: ='Dilution (TSM)'!C14 | D14: mm
B15: Pessimistic value / share | C15: =DCF!C76 | D15: USD/share
B16: Neutral value / share | C16: =DCF!C39 | D16: USD/share
B17: Optimistic value / share | C17: =DCF!C113 | D17: USD/share
B18: Pessimistic equity value | C18: =DCF!C74 | D18: USD mm
B19: Neutral equity value | C19: =DCF!C37 | D19: USD mm
B20: Optimistic equity value | C20: =DCF!C111 | D20: USD mm
B21: Pessimistic EV | C21: =DCF!C72 | D21: USD mm
B22: Neutral EV | C22: =DCF!C35 | D22: USD mm
B23: Optimistic EV | C23: =DCF!C109 | D23: USD mm
B24: Pessimistic weight | C24: =Inputs!G63
B25: Neutral weight | C25: =Inputs!H63
B26: Optimistic weight | C26: =Inputs!I63
B27: Weight sum | C27: =SUM(C24:C26)

Sheet Agent Log
B2: AGENT LOG (audit trail for this valuation run)
B3: Write high-level rationales & sources. Do NOT store private chain-of-thought. Keep entries concise, factual, and reproducible.
B5: RUN METADATA
B6: Run ID | D6: Status
B7: Start time (UTC) | D7: End time (UTC)
B8: Ticker | C8: =Inputs!C4 | D8: Company | E8: =Inputs!E4
B9: Template version | C9: v3-sheets-logbook | D9: Agent version (git SHA)
B10: Model (provider/model) | D10: Sheets engine | E10: Google Sheets API
B11: Data sources | D11: Currency / Units | E11: =Inputs!C5
B12: Tokens (total) | D12: Cost (USD)
B13: Notes
B15: ACTION LEDGER (one row per step/tool call)
B16: Step | C16: TS (UTC) | D16: Phase | E16: Action | F16: Target | G16: Inputs (summary) | H16: Outputs (summary) | I16: Citations | J16: Notes
B17: 1
B18: 2
B19: 3
B20: 4
B21: 5
B22: 6
B23: 7
B24: 8
B25: 9
B26: 10
B27: 11
B28: 12
... B216: 200
B219: ASSUMPTION JOURNAL (what the agent changed + why)
B220: Assumption | C220: Scenario | D220: Value | E220: Unit | F220: Where in model | G220: Source | H220: Method | I220: Rationale (high-level) | J220: Confidence | K220: Reviewer
B249: STORY JOURNAL (scenario narrative -> valuation linkage)
B250: Scenario | C250: Story claim | D250: Linked metric / range | E250: Supporting evidence | F250: Risk to claim | G250: Catalyst | H250: Update trigger | I250: Confidence | J250: Reviewer
B303: RUN NARRATIVE SUMMARY (1-2 paragraphs, reproducible)
